2025-08-20 21:58:28,169 ERROR backend.app Exception on /admin/login [POST]
Traceback (most recent call last):
  File "C:\PythonProject\MyPortfolio\.venv\Lib\site-packages\flask\app.py", line 1473, in wsgi_app
    response = self.full_dispatch_request()
               ^^^^^^^^^^^^^^^^^^^^^^^^^^^^
  File "C:\PythonProject\MyPortfolio\.venv\Lib\site-packages\flask\app.py", line 882, in full_dispatch_request
    rv = self.handle_user_exception(e)
         ^^^^^^^^^^^^^^^^^^^^^^^^^^^^^
  File "C:\PythonProject\MyPortfolio\.venv\Lib\site-packages\flask\app.py", line 880, in full_dispatch_request
    rv = self.dispatch_request()
         ^^^^^^^^^^^^^^^^^^^^^^^
  File "C:\PythonProject\MyPortfolio\.venv\Lib\site-packages\flask\app.py", line 865, in dispatch_request
    return self.ensure_sync(self.view_functions[rule.endpoint])(**view_args)  # type: ignore[no-any-return]
           ^^^^^^^^^^^^^^^^^^^^^^^^^^^^^^^^^^^^^^^^^^^^^^^^^^^^^^^^^^^^^^^^^
  File "C:\PythonProject\MyPortfolio\myPortfolio\backend\auth.py", line 23, in login
    session["admin_logged_in"] = True
    ~~~~~~~^^^^^^^^^^^^^^^^^^^
  File "C:\PythonProject\MyPortfolio\.venv\Lib\site-packages\flask\sessions.py", line 102, in _fail
    raise RuntimeError(
RuntimeError: The session is unavailable because no secret key was set.  Set the secret_key on the application to something unique and secret.
2025-08-20 21:58:28,171 ERROR backend.app Server error: 500 Internal Server Error: The server encountered an internal error and was unable to complete your request. Either the server is overloaded or there is an error in the application.
Traceback (most recent call last):
  File "C:\PythonProject\MyPortfolio\.venv\Lib\site-packages\flask\app.py", line 1473, in wsgi_app
    response = self.full_dispatch_request()
               ^^^^^^^^^^^^^^^^^^^^^^^^^^^^
  File "C:\PythonProject\MyPortfolio\.venv\Lib\site-packages\flask\app.py", line 882, in full_dispatch_request
    rv = self.handle_user_exception(e)
         ^^^^^^^^^^^^^^^^^^^^^^^^^^^^^
  File "C:\PythonProject\MyPortfolio\.venv\Lib\site-packages\flask\app.py", line 880, in full_dispatch_request
    rv = self.dispatch_request()
         ^^^^^^^^^^^^^^^^^^^^^^^
  File "C:\PythonProject\MyPortfolio\.venv\Lib\site-packages\flask\app.py", line 865, in dispatch_request
    return self.ensure_sync(self.view_functions[rule.endpoint])(**view_args)  # type: ignore[no-any-return]
           ^^^^^^^^^^^^^^^^^^^^^^^^^^^^^^^^^^^^^^^^^^^^^^^^^^^^^^^^^^^^^^^^^
  File "C:\PythonProject\MyPortfolio\myPortfolio\backend\auth.py", line 23, in login
    session["admin_logged_in"] = True
    ~~~~~~~^^^^^^^^^^^^^^^^^^^
  File "C:\PythonProject\MyPortfolio\.venv\Lib\site-packages\flask\sessions.py", line 102, in _fail
    raise RuntimeError(
RuntimeError: The session is unavailable because no secret key was set.  Set the secret_key on the application to something unique and secret.
2025-08-20 22:05:28,813 ERROR backend.app Exception on /admin/login [POST]
Traceback (most recent call last):
  File "C:\PythonProject\MyPortfolio\.venv\Lib\site-packages\flask\app.py", line 1473, in wsgi_app
    response = self.full_dispatch_request()
               ^^^^^^^^^^^^^^^^^^^^^^^^^^^^
  File "C:\PythonProject\MyPortfolio\.venv\Lib\site-packages\flask\app.py", line 882, in full_dispatch_request
    rv = self.handle_user_exception(e)
         ^^^^^^^^^^^^^^^^^^^^^^^^^^^^^
  File "C:\PythonProject\MyPortfolio\.venv\Lib\site-packages\flask\app.py", line 880, in full_dispatch_request
    rv = self.dispatch_request()
         ^^^^^^^^^^^^^^^^^^^^^^^
  File "C:\PythonProject\MyPortfolio\.venv\Lib\site-packages\flask\app.py", line 865, in dispatch_request
    return self.ensure_sync(self.view_functions[rule.endpoint])(**view_args)  # type: ignore[no-any-return]
           ^^^^^^^^^^^^^^^^^^^^^^^^^^^^^^^^^^^^^^^^^^^^^^^^^^^^^^^^^^^^^^^^^
  File "C:\PythonProject\MyPortfolio\myPortfolio\backend\auth.py", line 23, in login
    session["admin_logged_in"] = True
    ~~~~~~~^^^^^^^^^^^^^^^^^^^
  File "C:\PythonProject\MyPortfolio\.venv\Lib\site-packages\flask\sessions.py", line 102, in _fail
    raise RuntimeError(
RuntimeError: The session is unavailable because no secret key was set.  Set the secret_key on the application to something unique and secret.
2025-08-20 22:05:28,815 ERROR backend.app Server error: 500 Internal Server Error: The server encountered an internal error and was unable to complete your request. Either the server is overloaded or there is an error in the application.
Traceback (most recent call last):
  File "C:\PythonProject\MyPortfolio\.venv\Lib\site-packages\flask\app.py", line 1473, in wsgi_app
    response = self.full_dispatch_request()
               ^^^^^^^^^^^^^^^^^^^^^^^^^^^^
  File "C:\PythonProject\MyPortfolio\.venv\Lib\site-packages\flask\app.py", line 882, in full_dispatch_request
    rv = self.handle_user_exception(e)
         ^^^^^^^^^^^^^^^^^^^^^^^^^^^^^
  File "C:\PythonProject\MyPortfolio\.venv\Lib\site-packages\flask\app.py", line 880, in full_dispatch_request
    rv = self.dispatch_request()
         ^^^^^^^^^^^^^^^^^^^^^^^
  File "C:\PythonProject\MyPortfolio\.venv\Lib\site-packages\flask\app.py", line 865, in dispatch_request
    return self.ensure_sync(self.view_functions[rule.endpoint])(**view_args)  # type: ignore[no-any-return]
           ^^^^^^^^^^^^^^^^^^^^^^^^^^^^^^^^^^^^^^^^^^^^^^^^^^^^^^^^^^^^^^^^^
  File "C:\PythonProject\MyPortfolio\myPortfolio\backend\auth.py", line 23, in login
    session["admin_logged_in"] = True
    ~~~~~~~^^^^^^^^^^^^^^^^^^^
  File "C:\PythonProject\MyPortfolio\.venv\Lib\site-packages\flask\sessions.py", line 102, in _fail
    raise RuntimeError(
RuntimeError: The session is unavailable because no secret key was set.  Set the secret_key on the application to something unique and secret.
2025-08-20 22:06:02,568 INFO backend.app Successfully fetched 11 repositories for user Zarifwebme
2025-08-20 22:06:45,870 INFO backend.app Successfully fetched 11 repositories for user Zarifwebme
2025-08-20 22:07:27,669 ERROR backend.app Exception on /admin/login [POST]
Traceback (most recent call last):
  File "C:\PythonProject\MyPortfolio\.venv\Lib\site-packages\flask\app.py", line 1473, in wsgi_app
    response = self.full_dispatch_request()
               ^^^^^^^^^^^^^^^^^^^^^^^^^^^^
  File "C:\PythonProject\MyPortfolio\.venv\Lib\site-packages\flask\app.py", line 882, in full_dispatch_request
    rv = self.handle_user_exception(e)
         ^^^^^^^^^^^^^^^^^^^^^^^^^^^^^
  File "C:\PythonProject\MyPortfolio\.venv\Lib\site-packages\flask\app.py", line 880, in full_dispatch_request
    rv = self.dispatch_request()
         ^^^^^^^^^^^^^^^^^^^^^^^
  File "C:\PythonProject\MyPortfolio\.venv\Lib\site-packages\flask\app.py", line 865, in dispatch_request
    return self.ensure_sync(self.view_functions[rule.endpoint])(**view_args)  # type: ignore[no-any-return]
           ^^^^^^^^^^^^^^^^^^^^^^^^^^^^^^^^^^^^^^^^^^^^^^^^^^^^^^^^^^^^^^^^^
  File "C:\PythonProject\MyPortfolio\myPortfolio\backend\auth.py", line 23, in login
    session["admin_logged_in"] = True
    ~~~~~~~^^^^^^^^^^^^^^^^^^^
  File "C:\PythonProject\MyPortfolio\.venv\Lib\site-packages\flask\sessions.py", line 102, in _fail
    raise RuntimeError(
RuntimeError: The session is unavailable because no secret key was set.  Set the secret_key on the application to something unique and secret.
2025-08-20 22:07:27,669 ERROR backend.app Server error: 500 Internal Server Error: The server encountered an internal error and was unable to complete your request. Either the server is overloaded or there is an error in the application.
Traceback (most recent call last):
  File "C:\PythonProject\MyPortfolio\.venv\Lib\site-packages\flask\app.py", line 1473, in wsgi_app
    response = self.full_dispatch_request()
               ^^^^^^^^^^^^^^^^^^^^^^^^^^^^
  File "C:\PythonProject\MyPortfolio\.venv\Lib\site-packages\flask\app.py", line 882, in full_dispatch_request
    rv = self.handle_user_exception(e)
         ^^^^^^^^^^^^^^^^^^^^^^^^^^^^^
  File "C:\PythonProject\MyPortfolio\.venv\Lib\site-packages\flask\app.py", line 880, in full_dispatch_request
    rv = self.dispatch_request()
         ^^^^^^^^^^^^^^^^^^^^^^^
  File "C:\PythonProject\MyPortfolio\.venv\Lib\site-packages\flask\app.py", line 865, in dispatch_request
    return self.ensure_sync(self.view_functions[rule.endpoint])(**view_args)  # type: ignore[no-any-return]
           ^^^^^^^^^^^^^^^^^^^^^^^^^^^^^^^^^^^^^^^^^^^^^^^^^^^^^^^^^^^^^^^^^
  File "C:\PythonProject\MyPortfolio\myPortfolio\backend\auth.py", line 23, in login
    session["admin_logged_in"] = True
    ~~~~~~~^^^^^^^^^^^^^^^^^^^
  File "C:\PythonProject\MyPortfolio\.venv\Lib\site-packages\flask\sessions.py", line 102, in _fail
    raise RuntimeError(
RuntimeError: The session is unavailable because no secret key was set.  Set the secret_key on the application to something unique and secret.
2025-08-21 15:05:04,883 ERROR backend.app Exception on /admin/ [GET]
Traceback (most recent call last):
  File "C:\PythonProject\MyPortfolio\.venv\Lib\site-packages\sqlalchemy\engine\base.py", line 1967, in _exec_single_context
    self.dialect.do_execute(
  File "C:\PythonProject\MyPortfolio\.venv\Lib\site-packages\sqlalchemy\engine\default.py", line 941, in do_execute
    cursor.execute(statement, parameters)
sqlite3.OperationalError: no such column: contact.first_name

The above exception was the direct cause of the following exception:

Traceback (most recent call last):
  File "C:\PythonProject\MyPortfolio\.venv\Lib\site-packages\flask\app.py", line 1473, in wsgi_app
    response = self.full_dispatch_request()
               ^^^^^^^^^^^^^^^^^^^^^^^^^^^^
  File "C:\PythonProject\MyPortfolio\.venv\Lib\site-packages\flask\app.py", line 882, in full_dispatch_request
    rv = self.handle_user_exception(e)
         ^^^^^^^^^^^^^^^^^^^^^^^^^^^^^
  File "C:\PythonProject\MyPortfolio\.venv\Lib\site-packages\flask\app.py", line 880, in full_dispatch_request
    rv = self.dispatch_request()
         ^^^^^^^^^^^^^^^^^^^^^^^
  File "C:\PythonProject\MyPortfolio\.venv\Lib\site-packages\flask\app.py", line 865, in dispatch_request
    return self.ensure_sync(self.view_functions[rule.endpoint])(**view_args)  # type: ignore[no-any-return]
           ^^^^^^^^^^^^^^^^^^^^^^^^^^^^^^^^^^^^^^^^^^^^^^^^^^^^^^^^^^^^^^^^^
  File "C:\PythonProject\MyPortfolio\myPortfolio\backend\auth.py", line 13, in wrapped
    return view_func(*args, **kwargs)
           ^^^^^^^^^^^^^^^^^^^^^^^^^^
  File "C:\PythonProject\MyPortfolio\myPortfolio\backend\admin.py", line 18, in dashboard
    "contacts": Contact.query.count(),
                ^^^^^^^^^^^^^^^^^^^^^
  File "C:\PythonProject\MyPortfolio\.venv\Lib\site-packages\sqlalchemy\orm\query.py", line 3113, in count
    self._legacy_from_self(col).enable_eagerloads(False).scalar()
  File "C:\PythonProject\MyPortfolio\.venv\Lib\site-packages\sqlalchemy\orm\query.py", line 2805, in scalar
    ret = self.one()
          ^^^^^^^^^^
  File "C:\PythonProject\MyPortfolio\.venv\Lib\site-packages\sqlalchemy\orm\query.py", line 2778, in one
    return self._iter().one()  # type: ignore
           ^^^^^^^^^^^^
  File "C:\PythonProject\MyPortfolio\.venv\Lib\site-packages\sqlalchemy\orm\query.py", line 2827, in _iter
    result: Union[ScalarResult[_T], Result[_T]] = self.session.execute(
                                                  ^^^^^^^^^^^^^^^^^^^^^
  File "C:\PythonProject\MyPortfolio\.venv\Lib\site-packages\sqlalchemy\orm\session.py", line 2362, in execute
    return self._execute_internal(
           ^^^^^^^^^^^^^^^^^^^^^^^
  File "C:\PythonProject\MyPortfolio\.venv\Lib\site-packages\sqlalchemy\orm\session.py", line 2247, in _execute_internal
    result: Result[Any] = compile_state_cls.orm_execute_statement(
                          ^^^^^^^^^^^^^^^^^^^^^^^^^^^^^^^^^^^^^^^^
  File "C:\PythonProject\MyPortfolio\.venv\Lib\site-packages\sqlalchemy\orm\context.py", line 305, in orm_execute_statement
    result = conn.execute(
             ^^^^^^^^^^^^^
  File "C:\PythonProject\MyPortfolio\.venv\Lib\site-packages\sqlalchemy\engine\base.py", line 1418, in execute
    return meth(
           ^^^^^
  File "C:\PythonProject\MyPortfolio\.venv\Lib\site-packages\sqlalchemy\sql\elements.py", line 515, in _execute_on_connection
    return connection._execute_clauseelement(
           ^^^^^^^^^^^^^^^^^^^^^^^^^^^^^^^^^^
  File "C:\PythonProject\MyPortfolio\.venv\Lib\site-packages\sqlalchemy\engine\base.py", line 1640, in _execute_clauseelement
    ret = self._execute_context(
          ^^^^^^^^^^^^^^^^^^^^^^
  File "C:\PythonProject\MyPortfolio\.venv\Lib\site-packages\sqlalchemy\engine\base.py", line 1846, in _execute_context
    return self._exec_single_context(
           ^^^^^^^^^^^^^^^^^^^^^^^^^^
  File "C:\PythonProject\MyPortfolio\.venv\Lib\site-packages\sqlalchemy\engine\base.py", line 1986, in _exec_single_context
    self._handle_dbapi_exception(
  File "C:\PythonProject\MyPortfolio\.venv\Lib\site-packages\sqlalchemy\engine\base.py", line 2355, in _handle_dbapi_exception
    raise sqlalchemy_exception.with_traceback(exc_info[2]) from e
  File "C:\PythonProject\MyPortfolio\.venv\Lib\site-packages\sqlalchemy\engine\base.py", line 1967, in _exec_single_context
    self.dialect.do_execute(
  File "C:\PythonProject\MyPortfolio\.venv\Lib\site-packages\sqlalchemy\engine\default.py", line 941, in do_execute
    cursor.execute(statement, parameters)
sqlalchemy.exc.OperationalError: (sqlite3.OperationalError) no such column: contact.first_name
[SQL: SELECT count(*) AS count_1 
FROM (SELECT contact.id AS contact_id, contact.first_name AS contact_first_name, contact.last_name AS contact_last_name, contact.phone_number AS contact_phone_number, contact.message AS contact_message, contact.created_at AS contact_created_at 
FROM contact) AS anon_1]
(Background on this error at: https://sqlalche.me/e/20/e3q8)
2025-08-21 15:05:05,054 ERROR backend.app Server error: 500 Internal Server Error: The server encountered an internal error and was unable to complete your request. Either the server is overloaded or there is an error in the application.
Traceback (most recent call last):
  File "C:\PythonProject\MyPortfolio\.venv\Lib\site-packages\sqlalchemy\engine\base.py", line 1967, in _exec_single_context
    self.dialect.do_execute(
  File "C:\PythonProject\MyPortfolio\.venv\Lib\site-packages\sqlalchemy\engine\default.py", line 941, in do_execute
    cursor.execute(statement, parameters)
sqlite3.OperationalError: no such column: contact.first_name

The above exception was the direct cause of the following exception:

Traceback (most recent call last):
  File "C:\PythonProject\MyPortfolio\.venv\Lib\site-packages\flask\app.py", line 1473, in wsgi_app
    response = self.full_dispatch_request()
               ^^^^^^^^^^^^^^^^^^^^^^^^^^^^
  File "C:\PythonProject\MyPortfolio\.venv\Lib\site-packages\flask\app.py", line 882, in full_dispatch_request
    rv = self.handle_user_exception(e)
         ^^^^^^^^^^^^^^^^^^^^^^^^^^^^^
  File "C:\PythonProject\MyPortfolio\.venv\Lib\site-packages\flask\app.py", line 880, in full_dispatch_request
    rv = self.dispatch_request()
         ^^^^^^^^^^^^^^^^^^^^^^^
  File "C:\PythonProject\MyPortfolio\.venv\Lib\site-packages\flask\app.py", line 865, in dispatch_request
    return self.ensure_sync(self.view_functions[rule.endpoint])(**view_args)  # type: ignore[no-any-return]
           ^^^^^^^^^^^^^^^^^^^^^^^^^^^^^^^^^^^^^^^^^^^^^^^^^^^^^^^^^^^^^^^^^
  File "C:\PythonProject\MyPortfolio\myPortfolio\backend\auth.py", line 13, in wrapped
    return view_func(*args, **kwargs)
           ^^^^^^^^^^^^^^^^^^^^^^^^^^
  File "C:\PythonProject\MyPortfolio\myPortfolio\backend\admin.py", line 18, in dashboard
    "contacts": Contact.query.count(),
                ^^^^^^^^^^^^^^^^^^^^^
  File "C:\PythonProject\MyPortfolio\.venv\Lib\site-packages\sqlalchemy\orm\query.py", line 3113, in count
    self._legacy_from_self(col).enable_eagerloads(False).scalar()
  File "C:\PythonProject\MyPortfolio\.venv\Lib\site-packages\sqlalchemy\orm\query.py", line 2805, in scalar
    ret = self.one()
          ^^^^^^^^^^
  File "C:\PythonProject\MyPortfolio\.venv\Lib\site-packages\sqlalchemy\orm\query.py", line 2778, in one
    return self._iter().one()  # type: ignore
           ^^^^^^^^^^^^
  File "C:\PythonProject\MyPortfolio\.venv\Lib\site-packages\sqlalchemy\orm\query.py", line 2827, in _iter
    result: Union[ScalarResult[_T], Result[_T]] = self.session.execute(
                                                  ^^^^^^^^^^^^^^^^^^^^^
  File "C:\PythonProject\MyPortfolio\.venv\Lib\site-packages\sqlalchemy\orm\session.py", line 2362, in execute
    return self._execute_internal(
           ^^^^^^^^^^^^^^^^^^^^^^^
  File "C:\PythonProject\MyPortfolio\.venv\Lib\site-packages\sqlalchemy\orm\session.py", line 2247, in _execute_internal
    result: Result[Any] = compile_state_cls.orm_execute_statement(
                          ^^^^^^^^^^^^^^^^^^^^^^^^^^^^^^^^^^^^^^^^
  File "C:\PythonProject\MyPortfolio\.venv\Lib\site-packages\sqlalchemy\orm\context.py", line 305, in orm_execute_statement
    result = conn.execute(
             ^^^^^^^^^^^^^
  File "C:\PythonProject\MyPortfolio\.venv\Lib\site-packages\sqlalchemy\engine\base.py", line 1418, in execute
    return meth(
           ^^^^^
  File "C:\PythonProject\MyPortfolio\.venv\Lib\site-packages\sqlalchemy\sql\elements.py", line 515, in _execute_on_connection
    return connection._execute_clauseelement(
           ^^^^^^^^^^^^^^^^^^^^^^^^^^^^^^^^^^
  File "C:\PythonProject\MyPortfolio\.venv\Lib\site-packages\sqlalchemy\engine\base.py", line 1640, in _execute_clauseelement
    ret = self._execute_context(
          ^^^^^^^^^^^^^^^^^^^^^^
  File "C:\PythonProject\MyPortfolio\.venv\Lib\site-packages\sqlalchemy\engine\base.py", line 1846, in _execute_context
    return self._exec_single_context(
           ^^^^^^^^^^^^^^^^^^^^^^^^^^
  File "C:\PythonProject\MyPortfolio\.venv\Lib\site-packages\sqlalchemy\engine\base.py", line 1986, in _exec_single_context
    self._handle_dbapi_exception(
  File "C:\PythonProject\MyPortfolio\.venv\Lib\site-packages\sqlalchemy\engine\base.py", line 2355, in _handle_dbapi_exception
    raise sqlalchemy_exception.with_traceback(exc_info[2]) from e
  File "C:\PythonProject\MyPortfolio\.venv\Lib\site-packages\sqlalchemy\engine\base.py", line 1967, in _exec_single_context
    self.dialect.do_execute(
  File "C:\PythonProject\MyPortfolio\.venv\Lib\site-packages\sqlalchemy\engine\default.py", line 941, in do_execute
    cursor.execute(statement, parameters)
sqlalchemy.exc.OperationalError: (sqlite3.OperationalError) no such column: contact.first_name
[SQL: SELECT count(*) AS count_1 
FROM (SELECT contact.id AS contact_id, contact.first_name AS contact_first_name, contact.last_name AS contact_last_name, contact.phone_number AS contact_phone_number, contact.message AS contact_message, contact.created_at AS contact_created_at 
FROM contact) AS anon_1]
(Background on this error at: https://sqlalche.me/e/20/e3q8)
2025-08-21 15:05:09,969 ERROR backend.app Exception on /admin/ [GET]
Traceback (most recent call last):
  File "C:\PythonProject\MyPortfolio\.venv\Lib\site-packages\sqlalchemy\engine\base.py", line 1967, in _exec_single_context
    self.dialect.do_execute(
  File "C:\PythonProject\MyPortfolio\.venv\Lib\site-packages\sqlalchemy\engine\default.py", line 941, in do_execute
    cursor.execute(statement, parameters)
sqlite3.OperationalError: no such column: contact.first_name

The above exception was the direct cause of the following exception:

Traceback (most recent call last):
  File "C:\PythonProject\MyPortfolio\.venv\Lib\site-packages\flask\app.py", line 1473, in wsgi_app
    response = self.full_dispatch_request()
               ^^^^^^^^^^^^^^^^^^^^^^^^^^^^
  File "C:\PythonProject\MyPortfolio\.venv\Lib\site-packages\flask\app.py", line 882, in full_dispatch_request
    rv = self.handle_user_exception(e)
         ^^^^^^^^^^^^^^^^^^^^^^^^^^^^^
  File "C:\PythonProject\MyPortfolio\.venv\Lib\site-packages\flask\app.py", line 880, in full_dispatch_request
    rv = self.dispatch_request()
         ^^^^^^^^^^^^^^^^^^^^^^^
  File "C:\PythonProject\MyPortfolio\.venv\Lib\site-packages\flask\app.py", line 865, in dispatch_request
    return self.ensure_sync(self.view_functions[rule.endpoint])(**view_args)  # type: ignore[no-any-return]
           ^^^^^^^^^^^^^^^^^^^^^^^^^^^^^^^^^^^^^^^^^^^^^^^^^^^^^^^^^^^^^^^^^
  File "C:\PythonProject\MyPortfolio\myPortfolio\backend\auth.py", line 13, in wrapped
    return view_func(*args, **kwargs)
           ^^^^^^^^^^^^^^^^^^^^^^^^^^
  File "C:\PythonProject\MyPortfolio\myPortfolio\backend\admin.py", line 18, in dashboard
    "contacts": Contact.query.count(),
                ^^^^^^^^^^^^^^^^^^^^^
  File "C:\PythonProject\MyPortfolio\.venv\Lib\site-packages\sqlalchemy\orm\query.py", line 3113, in count
    self._legacy_from_self(col).enable_eagerloads(False).scalar()
  File "C:\PythonProject\MyPortfolio\.venv\Lib\site-packages\sqlalchemy\orm\query.py", line 2805, in scalar
    ret = self.one()
          ^^^^^^^^^^
  File "C:\PythonProject\MyPortfolio\.venv\Lib\site-packages\sqlalchemy\orm\query.py", line 2778, in one
    return self._iter().one()  # type: ignore
           ^^^^^^^^^^^^
  File "C:\PythonProject\MyPortfolio\.venv\Lib\site-packages\sqlalchemy\orm\query.py", line 2827, in _iter
    result: Union[ScalarResult[_T], Result[_T]] = self.session.execute(
                                                  ^^^^^^^^^^^^^^^^^^^^^
  File "C:\PythonProject\MyPortfolio\.venv\Lib\site-packages\sqlalchemy\orm\session.py", line 2362, in execute
    return self._execute_internal(
           ^^^^^^^^^^^^^^^^^^^^^^^
  File "C:\PythonProject\MyPortfolio\.venv\Lib\site-packages\sqlalchemy\orm\session.py", line 2247, in _execute_internal
    result: Result[Any] = compile_state_cls.orm_execute_statement(
                          ^^^^^^^^^^^^^^^^^^^^^^^^^^^^^^^^^^^^^^^^
  File "C:\PythonProject\MyPortfolio\.venv\Lib\site-packages\sqlalchemy\orm\context.py", line 305, in orm_execute_statement
    result = conn.execute(
             ^^^^^^^^^^^^^
  File "C:\PythonProject\MyPortfolio\.venv\Lib\site-packages\sqlalchemy\engine\base.py", line 1418, in execute
    return meth(
           ^^^^^
  File "C:\PythonProject\MyPortfolio\.venv\Lib\site-packages\sqlalchemy\sql\elements.py", line 515, in _execute_on_connection
    return connection._execute_clauseelement(
           ^^^^^^^^^^^^^^^^^^^^^^^^^^^^^^^^^^
  File "C:\PythonProject\MyPortfolio\.venv\Lib\site-packages\sqlalchemy\engine\base.py", line 1640, in _execute_clauseelement
    ret = self._execute_context(
          ^^^^^^^^^^^^^^^^^^^^^^
  File "C:\PythonProject\MyPortfolio\.venv\Lib\site-packages\sqlalchemy\engine\base.py", line 1846, in _execute_context
    return self._exec_single_context(
           ^^^^^^^^^^^^^^^^^^^^^^^^^^
  File "C:\PythonProject\MyPortfolio\.venv\Lib\site-packages\sqlalchemy\engine\base.py", line 1986, in _exec_single_context
    self._handle_dbapi_exception(
  File "C:\PythonProject\MyPortfolio\.venv\Lib\site-packages\sqlalchemy\engine\base.py", line 2355, in _handle_dbapi_exception
    raise sqlalchemy_exception.with_traceback(exc_info[2]) from e
  File "C:\PythonProject\MyPortfolio\.venv\Lib\site-packages\sqlalchemy\engine\base.py", line 1967, in _exec_single_context
    self.dialect.do_execute(
  File "C:\PythonProject\MyPortfolio\.venv\Lib\site-packages\sqlalchemy\engine\default.py", line 941, in do_execute
    cursor.execute(statement, parameters)
sqlalchemy.exc.OperationalError: (sqlite3.OperationalError) no such column: contact.first_name
[SQL: SELECT count(*) AS count_1 
FROM (SELECT contact.id AS contact_id, contact.first_name AS contact_first_name, contact.last_name AS contact_last_name, contact.phone_number AS contact_phone_number, contact.message AS contact_message, contact.created_at AS contact_created_at 
FROM contact) AS anon_1]
(Background on this error at: https://sqlalche.me/e/20/e3q8)
2025-08-21 15:05:09,976 ERROR backend.app Server error: 500 Internal Server Error: The server encountered an internal error and was unable to complete your request. Either the server is overloaded or there is an error in the application.
Traceback (most recent call last):
  File "C:\PythonProject\MyPortfolio\.venv\Lib\site-packages\sqlalchemy\engine\base.py", line 1967, in _exec_single_context
    self.dialect.do_execute(
  File "C:\PythonProject\MyPortfolio\.venv\Lib\site-packages\sqlalchemy\engine\default.py", line 941, in do_execute
    cursor.execute(statement, parameters)
sqlite3.OperationalError: no such column: contact.first_name

The above exception was the direct cause of the following exception:

Traceback (most recent call last):
  File "C:\PythonProject\MyPortfolio\.venv\Lib\site-packages\flask\app.py", line 1473, in wsgi_app
    response = self.full_dispatch_request()
               ^^^^^^^^^^^^^^^^^^^^^^^^^^^^
  File "C:\PythonProject\MyPortfolio\.venv\Lib\site-packages\flask\app.py", line 882, in full_dispatch_request
    rv = self.handle_user_exception(e)
         ^^^^^^^^^^^^^^^^^^^^^^^^^^^^^
  File "C:\PythonProject\MyPortfolio\.venv\Lib\site-packages\flask\app.py", line 880, in full_dispatch_request
    rv = self.dispatch_request()
         ^^^^^^^^^^^^^^^^^^^^^^^
  File "C:\PythonProject\MyPortfolio\.venv\Lib\site-packages\flask\app.py", line 865, in dispatch_request
    return self.ensure_sync(self.view_functions[rule.endpoint])(**view_args)  # type: ignore[no-any-return]
           ^^^^^^^^^^^^^^^^^^^^^^^^^^^^^^^^^^^^^^^^^^^^^^^^^^^^^^^^^^^^^^^^^
  File "C:\PythonProject\MyPortfolio\myPortfolio\backend\auth.py", line 13, in wrapped
    return view_func(*args, **kwargs)
           ^^^^^^^^^^^^^^^^^^^^^^^^^^
  File "C:\PythonProject\MyPortfolio\myPortfolio\backend\admin.py", line 18, in dashboard
    "contacts": Contact.query.count(),
                ^^^^^^^^^^^^^^^^^^^^^
  File "C:\PythonProject\MyPortfolio\.venv\Lib\site-packages\sqlalchemy\orm\query.py", line 3113, in count
    self._legacy_from_self(col).enable_eagerloads(False).scalar()
  File "C:\PythonProject\MyPortfolio\.venv\Lib\site-packages\sqlalchemy\orm\query.py", line 2805, in scalar
    ret = self.one()
          ^^^^^^^^^^
  File "C:\PythonProject\MyPortfolio\.venv\Lib\site-packages\sqlalchemy\orm\query.py", line 2778, in one
    return self._iter().one()  # type: ignore
           ^^^^^^^^^^^^
  File "C:\PythonProject\MyPortfolio\.venv\Lib\site-packages\sqlalchemy\orm\query.py", line 2827, in _iter
    result: Union[ScalarResult[_T], Result[_T]] = self.session.execute(
                                                  ^^^^^^^^^^^^^^^^^^^^^
  File "C:\PythonProject\MyPortfolio\.venv\Lib\site-packages\sqlalchemy\orm\session.py", line 2362, in execute
    return self._execute_internal(
           ^^^^^^^^^^^^^^^^^^^^^^^
  File "C:\PythonProject\MyPortfolio\.venv\Lib\site-packages\sqlalchemy\orm\session.py", line 2247, in _execute_internal
    result: Result[Any] = compile_state_cls.orm_execute_statement(
                          ^^^^^^^^^^^^^^^^^^^^^^^^^^^^^^^^^^^^^^^^
  File "C:\PythonProject\MyPortfolio\.venv\Lib\site-packages\sqlalchemy\orm\context.py", line 305, in orm_execute_statement
    result = conn.execute(
             ^^^^^^^^^^^^^
  File "C:\PythonProject\MyPortfolio\.venv\Lib\site-packages\sqlalchemy\engine\base.py", line 1418, in execute
    return meth(
           ^^^^^
  File "C:\PythonProject\MyPortfolio\.venv\Lib\site-packages\sqlalchemy\sql\elements.py", line 515, in _execute_on_connection
    return connection._execute_clauseelement(
           ^^^^^^^^^^^^^^^^^^^^^^^^^^^^^^^^^^
  File "C:\PythonProject\MyPortfolio\.venv\Lib\site-packages\sqlalchemy\engine\base.py", line 1640, in _execute_clauseelement
    ret = self._execute_context(
          ^^^^^^^^^^^^^^^^^^^^^^
  File "C:\PythonProject\MyPortfolio\.venv\Lib\site-packages\sqlalchemy\engine\base.py", line 1846, in _execute_context
    return self._exec_single_context(
           ^^^^^^^^^^^^^^^^^^^^^^^^^^
  File "C:\PythonProject\MyPortfolio\.venv\Lib\site-packages\sqlalchemy\engine\base.py", line 1986, in _exec_single_context
    self._handle_dbapi_exception(
  File "C:\PythonProject\MyPortfolio\.venv\Lib\site-packages\sqlalchemy\engine\base.py", line 2355, in _handle_dbapi_exception
    raise sqlalchemy_exception.with_traceback(exc_info[2]) from e
  File "C:\PythonProject\MyPortfolio\.venv\Lib\site-packages\sqlalchemy\engine\base.py", line 1967, in _exec_single_context
    self.dialect.do_execute(
  File "C:\PythonProject\MyPortfolio\.venv\Lib\site-packages\sqlalchemy\engine\default.py", line 941, in do_execute
    cursor.execute(statement, parameters)
sqlalchemy.exc.OperationalError: (sqlite3.OperationalError) no such column: contact.first_name
[SQL: SELECT count(*) AS count_1 
FROM (SELECT contact.id AS contact_id, contact.first_name AS contact_first_name, contact.last_name AS contact_last_name, contact.phone_number AS contact_phone_number, contact.message AS contact_message, contact.created_at AS contact_created_at 
FROM contact) AS anon_1]
(Background on this error at: https://sqlalche.me/e/20/e3q8)
2025-08-21 15:05:13,765 ERROR backend.app Exception on /admin/ [GET]
Traceback (most recent call last):
  File "C:\PythonProject\MyPortfolio\.venv\Lib\site-packages\sqlalchemy\engine\base.py", line 1967, in _exec_single_context
    self.dialect.do_execute(
  File "C:\PythonProject\MyPortfolio\.venv\Lib\site-packages\sqlalchemy\engine\default.py", line 941, in do_execute
    cursor.execute(statement, parameters)
sqlite3.OperationalError: no such column: contact.first_name

The above exception was the direct cause of the following exception:

Traceback (most recent call last):
  File "C:\PythonProject\MyPortfolio\.venv\Lib\site-packages\flask\app.py", line 1473, in wsgi_app
    response = self.full_dispatch_request()
               ^^^^^^^^^^^^^^^^^^^^^^^^^^^^
  File "C:\PythonProject\MyPortfolio\.venv\Lib\site-packages\flask\app.py", line 882, in full_dispatch_request
    rv = self.handle_user_exception(e)
         ^^^^^^^^^^^^^^^^^^^^^^^^^^^^^
  File "C:\PythonProject\MyPortfolio\.venv\Lib\site-packages\flask\app.py", line 880, in full_dispatch_request
    rv = self.dispatch_request()
         ^^^^^^^^^^^^^^^^^^^^^^^
  File "C:\PythonProject\MyPortfolio\.venv\Lib\site-packages\flask\app.py", line 865, in dispatch_request
    return self.ensure_sync(self.view_functions[rule.endpoint])(**view_args)  # type: ignore[no-any-return]
           ^^^^^^^^^^^^^^^^^^^^^^^^^^^^^^^^^^^^^^^^^^^^^^^^^^^^^^^^^^^^^^^^^
  File "C:\PythonProject\MyPortfolio\myPortfolio\backend\auth.py", line 13, in wrapped
    return view_func(*args, **kwargs)
           ^^^^^^^^^^^^^^^^^^^^^^^^^^
  File "C:\PythonProject\MyPortfolio\myPortfolio\backend\admin.py", line 18, in dashboard
    "contacts": Contact.query.count(),
                ^^^^^^^^^^^^^^^^^^^^^
  File "C:\PythonProject\MyPortfolio\.venv\Lib\site-packages\sqlalchemy\orm\query.py", line 3113, in count
    self._legacy_from_self(col).enable_eagerloads(False).scalar()
  File "C:\PythonProject\MyPortfolio\.venv\Lib\site-packages\sqlalchemy\orm\query.py", line 2805, in scalar
    ret = self.one()
          ^^^^^^^^^^
  File "C:\PythonProject\MyPortfolio\.venv\Lib\site-packages\sqlalchemy\orm\query.py", line 2778, in one
    return self._iter().one()  # type: ignore
           ^^^^^^^^^^^^
  File "C:\PythonProject\MyPortfolio\.venv\Lib\site-packages\sqlalchemy\orm\query.py", line 2827, in _iter
    result: Union[ScalarResult[_T], Result[_T]] = self.session.execute(
                                                  ^^^^^^^^^^^^^^^^^^^^^
  File "C:\PythonProject\MyPortfolio\.venv\Lib\site-packages\sqlalchemy\orm\session.py", line 2362, in execute
    return self._execute_internal(
           ^^^^^^^^^^^^^^^^^^^^^^^
  File "C:\PythonProject\MyPortfolio\.venv\Lib\site-packages\sqlalchemy\orm\session.py", line 2247, in _execute_internal
    result: Result[Any] = compile_state_cls.orm_execute_statement(
                          ^^^^^^^^^^^^^^^^^^^^^^^^^^^^^^^^^^^^^^^^
  File "C:\PythonProject\MyPortfolio\.venv\Lib\site-packages\sqlalchemy\orm\context.py", line 305, in orm_execute_statement
    result = conn.execute(
             ^^^^^^^^^^^^^
  File "C:\PythonProject\MyPortfolio\.venv\Lib\site-packages\sqlalchemy\engine\base.py", line 1418, in execute
    return meth(
           ^^^^^
  File "C:\PythonProject\MyPortfolio\.venv\Lib\site-packages\sqlalchemy\sql\elements.py", line 515, in _execute_on_connection
    return connection._execute_clauseelement(
           ^^^^^^^^^^^^^^^^^^^^^^^^^^^^^^^^^^
  File "C:\PythonProject\MyPortfolio\.venv\Lib\site-packages\sqlalchemy\engine\base.py", line 1640, in _execute_clauseelement
    ret = self._execute_context(
          ^^^^^^^^^^^^^^^^^^^^^^
  File "C:\PythonProject\MyPortfolio\.venv\Lib\site-packages\sqlalchemy\engine\base.py", line 1846, in _execute_context
    return self._exec_single_context(
           ^^^^^^^^^^^^^^^^^^^^^^^^^^
  File "C:\PythonProject\MyPortfolio\.venv\Lib\site-packages\sqlalchemy\engine\base.py", line 1986, in _exec_single_context
    self._handle_dbapi_exception(
  File "C:\PythonProject\MyPortfolio\.venv\Lib\site-packages\sqlalchemy\engine\base.py", line 2355, in _handle_dbapi_exception
    raise sqlalchemy_exception.with_traceback(exc_info[2]) from e
  File "C:\PythonProject\MyPortfolio\.venv\Lib\site-packages\sqlalchemy\engine\base.py", line 1967, in _exec_single_context
    self.dialect.do_execute(
  File "C:\PythonProject\MyPortfolio\.venv\Lib\site-packages\sqlalchemy\engine\default.py", line 941, in do_execute
    cursor.execute(statement, parameters)
sqlalchemy.exc.OperationalError: (sqlite3.OperationalError) no such column: contact.first_name
[SQL: SELECT count(*) AS count_1 
FROM (SELECT contact.id AS contact_id, contact.first_name AS contact_first_name, contact.last_name AS contact_last_name, contact.phone_number AS contact_phone_number, contact.message AS contact_message, contact.created_at AS contact_created_at 
FROM contact) AS anon_1]
(Background on this error at: https://sqlalche.me/e/20/e3q8)
2025-08-21 15:05:13,781 ERROR backend.app Server error: 500 Internal Server Error: The server encountered an internal error and was unable to complete your request. Either the server is overloaded or there is an error in the application.
Traceback (most recent call last):
  File "C:\PythonProject\MyPortfolio\.venv\Lib\site-packages\sqlalchemy\engine\base.py", line 1967, in _exec_single_context
    self.dialect.do_execute(
  File "C:\PythonProject\MyPortfolio\.venv\Lib\site-packages\sqlalchemy\engine\default.py", line 941, in do_execute
    cursor.execute(statement, parameters)
sqlite3.OperationalError: no such column: contact.first_name

The above exception was the direct cause of the following exception:

Traceback (most recent call last):
  File "C:\PythonProject\MyPortfolio\.venv\Lib\site-packages\flask\app.py", line 1473, in wsgi_app
    response = self.full_dispatch_request()
               ^^^^^^^^^^^^^^^^^^^^^^^^^^^^
  File "C:\PythonProject\MyPortfolio\.venv\Lib\site-packages\flask\app.py", line 882, in full_dispatch_request
    rv = self.handle_user_exception(e)
         ^^^^^^^^^^^^^^^^^^^^^^^^^^^^^
  File "C:\PythonProject\MyPortfolio\.venv\Lib\site-packages\flask\app.py", line 880, in full_dispatch_request
    rv = self.dispatch_request()
         ^^^^^^^^^^^^^^^^^^^^^^^
  File "C:\PythonProject\MyPortfolio\.venv\Lib\site-packages\flask\app.py", line 865, in dispatch_request
    return self.ensure_sync(self.view_functions[rule.endpoint])(**view_args)  # type: ignore[no-any-return]
           ^^^^^^^^^^^^^^^^^^^^^^^^^^^^^^^^^^^^^^^^^^^^^^^^^^^^^^^^^^^^^^^^^
  File "C:\PythonProject\MyPortfolio\myPortfolio\backend\auth.py", line 13, in wrapped
    return view_func(*args, **kwargs)
           ^^^^^^^^^^^^^^^^^^^^^^^^^^
  File "C:\PythonProject\MyPortfolio\myPortfolio\backend\admin.py", line 18, in dashboard
    "contacts": Contact.query.count(),
                ^^^^^^^^^^^^^^^^^^^^^
  File "C:\PythonProject\MyPortfolio\.venv\Lib\site-packages\sqlalchemy\orm\query.py", line 3113, in count
    self._legacy_from_self(col).enable_eagerloads(False).scalar()
  File "C:\PythonProject\MyPortfolio\.venv\Lib\site-packages\sqlalchemy\orm\query.py", line 2805, in scalar
    ret = self.one()
          ^^^^^^^^^^
  File "C:\PythonProject\MyPortfolio\.venv\Lib\site-packages\sqlalchemy\orm\query.py", line 2778, in one
    return self._iter().one()  # type: ignore
           ^^^^^^^^^^^^
  File "C:\PythonProject\MyPortfolio\.venv\Lib\site-packages\sqlalchemy\orm\query.py", line 2827, in _iter
    result: Union[ScalarResult[_T], Result[_T]] = self.session.execute(
                                                  ^^^^^^^^^^^^^^^^^^^^^
  File "C:\PythonProject\MyPortfolio\.venv\Lib\site-packages\sqlalchemy\orm\session.py", line 2362, in execute
    return self._execute_internal(
           ^^^^^^^^^^^^^^^^^^^^^^^
  File "C:\PythonProject\MyPortfolio\.venv\Lib\site-packages\sqlalchemy\orm\session.py", line 2247, in _execute_internal
    result: Result[Any] = compile_state_cls.orm_execute_statement(
                          ^^^^^^^^^^^^^^^^^^^^^^^^^^^^^^^^^^^^^^^^
  File "C:\PythonProject\MyPortfolio\.venv\Lib\site-packages\sqlalchemy\orm\context.py", line 305, in orm_execute_statement
    result = conn.execute(
             ^^^^^^^^^^^^^
  File "C:\PythonProject\MyPortfolio\.venv\Lib\site-packages\sqlalchemy\engine\base.py", line 1418, in execute
    return meth(
           ^^^^^
  File "C:\PythonProject\MyPortfolio\.venv\Lib\site-packages\sqlalchemy\sql\elements.py", line 515, in _execute_on_connection
    return connection._execute_clauseelement(
           ^^^^^^^^^^^^^^^^^^^^^^^^^^^^^^^^^^
  File "C:\PythonProject\MyPortfolio\.venv\Lib\site-packages\sqlalchemy\engine\base.py", line 1640, in _execute_clauseelement
    ret = self._execute_context(
          ^^^^^^^^^^^^^^^^^^^^^^
  File "C:\PythonProject\MyPortfolio\.venv\Lib\site-packages\sqlalchemy\engine\base.py", line 1846, in _execute_context
    return self._exec_single_context(
           ^^^^^^^^^^^^^^^^^^^^^^^^^^
  File "C:\PythonProject\MyPortfolio\.venv\Lib\site-packages\sqlalchemy\engine\base.py", line 1986, in _exec_single_context
    self._handle_dbapi_exception(
  File "C:\PythonProject\MyPortfolio\.venv\Lib\site-packages\sqlalchemy\engine\base.py", line 2355, in _handle_dbapi_exception
    raise sqlalchemy_exception.with_traceback(exc_info[2]) from e
  File "C:\PythonProject\MyPortfolio\.venv\Lib\site-packages\sqlalchemy\engine\base.py", line 1967, in _exec_single_context
    self.dialect.do_execute(
  File "C:\PythonProject\MyPortfolio\.venv\Lib\site-packages\sqlalchemy\engine\default.py", line 941, in do_execute
    cursor.execute(statement, parameters)
sqlalchemy.exc.OperationalError: (sqlite3.OperationalError) no such column: contact.first_name
[SQL: SELECT count(*) AS count_1 
FROM (SELECT contact.id AS contact_id, contact.first_name AS contact_first_name, contact.last_name AS contact_last_name, contact.phone_number AS contact_phone_number, contact.message AS contact_message, contact.created_at AS contact_created_at 
FROM contact) AS anon_1]
(Background on this error at: https://sqlalche.me/e/20/e3q8)
